Workbook

Sheet Financial Project
B1: Financial Plan
B2: Assumptions | D2: 2025 | E2: =+D2+1 -> 2026 | F2: =+E2+1 -> 2027 | G2: =+F2+1 -> 2028 | H2: =+G2+1 -> 2029 | I2: =+H2+1 -> 2030 | J2: =+I2+1 -> 2031 | K2: =+J2+1 -> 2032 | L2: =+K2+1 -> 2033 | M2: 2034 | N2: =+M2+1 -> 2035 | O2: =+N2+1 -> 2036 | P2: =+O2+1 -> 2037 | Q2: =+P2+1 -> 2038 | R2: =+Q2+1 -> 2039 | S2: =+R2+1 -> 2040 | T2: =+S2+1 -> 2041 | U2: =+T2+1 -> 2042 | ... AU2: =+AT2+1 -> 2068 | AV2: Total
B3: Annual Pay Increase-Wife | D3: 0.05 | E3: 0.05 | F3: 0.04 | G3: 0.04 | H3: 0.04 | I3: 0.04 | J3: 0.04 | K3: 0.04 | L3: 0.04 | M3: 0.04 | N3: 0.04 | O3: 0.04 | P3: 0.04 | Q3: 0.025 | R3: 0.025 | S3: 0.025 | T3: 0.025 | U3: 0.025 | V3: 0.025 | W3: 0.025 | X3: 0.025 | Y3: 0.025 | Z3: 0.025 | AA3: 0.025 | AB3: 0.025 | AC3: 0.025 | AD3: 0.025 | AE3: 0.025 | AF3: 0.025 | AG3: 0.025 | AH3: 0.025 | AI3: 0.025
B4: Annual Pay Increase-Husband | D4: 0.025 | E4: 0.025 | F4: 0.025 | G4: 0.025 | H4: 0.025 | I4: 0.025 | J4: 0.025 | K4: 0.025 | L4: 0.025 | M4: 0.025 | N4: 0.025 | O4: 0.025 | P4: 0.025 | Q4: 0.025 | R4: 0.025 | S4: 0.025 | T4: 0.025 | U4: 0.025 | V4: 0.025 | W4: 0.025 | X4: 0.025 | Y4: 0.025 | Z4: 0.025 | AA4: 0.025
B5: Inflation | D5: 0.025 | E5: 0.025 | F5: 0.025 | G5: 0.025 | H5: 0.025 | I5: 0.025 | J5: 0.025 | K5: 0.025 | L5: 0.025 | M5: 0.025 | N5: 0.025 | O5: 0.025 | P5: 0.025 | Q5: 0.025 | R5: 0.025 | S5: 0.025 | T5: 0.025 | U5: 0.025 | V5: 0.025 | W5: 0.025 | X5: 0.025 | Y5: 0.025 | Z5: 0.025 | AA5: 0.025 | AB5: 0.025 | AC5: 0.025 | AD5: 0.025 | AE5: 0.025 | AF5: 0.025 | AG5: 0.025 | AH5: 0.025 | AI5: 0.025 | AJ5: 0.025 | AK5: 0.025 | AL5: 0.025 | AM5: 0.025 | AN5: 0.025 | AO5: 0.025 | AP5: 0.025 | AQ5: 0.025 | AR5: 0.025 | AS5: 0.025 | AT5: 0.025 | AU5: 0.025
B6: 401KContribution-Wife | D6: 0.15 | E6: 0.15 | F6: 0.15 | G6: 0.15 | H6: 0.15 | I6: 0.15 | J6: 0.15 | K6: 0.15 | L6: 0.15 | M6: 0.15 | N6: 0.15 | O6: 0.15 | P6: 0.15 | Q6: 0.15 | R6: 0.15 | S6: 0.15 | T6: 0.15 | U6: 0.15 | V6: 0.15 | W6: 0.15 | X6: 0.15 | Y6: 0.15 | Z6: 0.15 | AA6: 0.15 | AB6: 0.15 | AC6: 0.15 | AD6: 0.15 | AE6: 0.15 | AF6: 0.15 | AG6: 0.15
B7: 401K Contribution-Husband | D7: 0.1 | E7: 0.1 | F7: 0.15 | G7: 0.15 | H7: 0.15 | I7: 0.15 | J7: 0.15 | K7: 0.15 | L7: 0.15 | M7: 0.15 | N7: 0.15 | O7: 0.15 | P7: 0.15 | Q7: 0.15 | R7: 0.15 | S7: 0.15 | T7: 0.15 | U7: 0.15 | V7: 0.15 | W7: 0.15 | X7: 0.15 | Y7: 0.15 | Z7: 0.15 | AA7: 0.15
B8: 401K ROI-Wife | D8: 0.08 | E8: 0.08 | F8: 0.08 | G8: 0.08 | H8: 0.08 | I8: 0.08 | J8: 0.08 | K8: 0.08 | L8: 0.08 | M8: 0.08 | N8: 0.08 | O8: 0.08 | P8: 0.08 | Q8: 0.08 | R8: 0.08 | S8: 0.08 | T8: 0.08 | U8: 0.08 | V8: 0.08 | W8: 0.08 | X8: 0.08 | Y8: 0.08 | Z8: 0.08 | AA8: 0.08 | AB8: 0.08 | AC8: 0.08 | AD8: 0.08 | AE8: 0.08 | AF8: 0.08 | AG8: 0.08 | AH8: 0.08 | AI8: 0.08 | AJ8: 0.08 | AK8: 0.08 | AL8: 0.08 | AM8: 0.08 | AN8: 0.08 | AO8: 0.08 | AP8: 0.08 | AQ8: 0.08 | AR8: 0.08 | AS8: 0.08 | AT8: 0.08 | AU8: 0.08
B9: 401K ROI-Husband | D9: 0.08 | E9: 0.08 | F9: 0.08 | G9: 0.08 | H9: 0.08 | I9: 0.08 | J9: 0.08 | K9: 0.08 | L9: 0.08 | M9: 0.08 | N9: 0.08 | O9: 0.08 | P9: 0.08 | Q9: 0.06 | R9: 0.06 | S9: 0.06 | T9: 0.06 | U9: 0.06 | V9: 0.06 | W9: 0.06 | X9: 0.06 | Y9: 0.06 | Z9: 0.06 | AA9: 0.06 | AB9: 0.06 | AC9: 0.06 | AD9: 0.06 | AE9: 0.06 | AF9: 0.06 | AG9: 0.06 | AH9: 0.06 | AI9: 0.06 | AJ9: 0.06 | AK9: 0.06 | AL9: 0.06 | AM9: 0.06 | AN9: 0.06 | AO9: 0.06 | AP9: 0.06 | AQ9: 0.06 | AR9: 0.06 | AS9: 0.06 | AT9: 0.06 | AU9: 0.06
B10: Roth IRA-ROI | D10: 0.08 | E10: 0.08 | F10: 0.08 | G10: 0.08 | H10: 0.08 | I10: 0.08 | J10: 0.08 | K10: 0.08 | L10: 0.08 | M10: 0.08 | N10: 0.08 | O10: 0.08 | P10: 0.08 | Q10: 0.06 | R10: 0.06 | S10: 0.06 | T10: 0.06 | U10: 0.06 | V10: 0.06 | W10: 0.06 | X10: 0.06 | Y10: 0.06 | Z10: 0.06 | AA10: 0.06 | AB10: 0.06 | AC10: 0.06 | AD10: 0.06 | AE10: 0.06 | AF10: 0.06 | AG10: 0.06 | AH10: 0.06 | AI10: 0.06 | AJ10: 0.06 | AK10: 0.06 | AL10: 0.06 | AM10: 0.06 | AN10: 0.06 | AO10: 0.06 | AP10: 0.06 | AQ10: 0.06 | AR10: 0.06 | AS10: 0.06 | AT10: 0.06 | AU10: 0.06
B11: Traditional IRA-ROI | J11: 0.08 | K11: 0.08 | L11: 0.08 | M11: 0.08 | N11: 0.08 | O11: 0.08 | P11: 0.08 | Q11: 0.06 | R11: 0.06 | S11: 0.06 | T11: 0.06 | U11: 0.06 | V11: 0.06 | W11: 0.06 | X11: 0.06 | Y11: 0.06 | Z11: 0.06 | AA11: 0.06 | AB11: 0.06 | AC11: 0.06 | AD11: 0.06 | AE11: 0.06 | AF11: 0.06 | AG11: 0.06 | AH11: 0.06 | AI11: 0.06 | AJ11: 0.06 | AK11: 0.06 | AL11: 0.06 | AM11: 0.06 | AN11: 0.06 | AO11: 0.06 | AP11: 0.06 | AQ11: 0.06 | AR11: 0.06 | AS11: 0.06 | AT11: 0.06 | AU11: 0.06
B12: Mortgage Interest Rate | D12: 0.0825 | E12: 0.0825 | F12: 0.0825 | G12: 0.0825 | H12: 0.0825 | I12: 0.0825 | J12: 0.0825 | K12: 0.0825 | L12: 0.0825 | M12: 0.0825 | N12: 0.0825 | O12: 0.0825 | P12: 0.0825 | Q12: 0.0825 | R12: 0.0825 | S12: 0.0825 | T12: 0.0825 | U12: 0.0825 | V12: 0.0825 | W12: 0.0825 | X12: 0.0825 | Y12: 0.0825 | Z12: 0.0825 | AA12: 0.0825 | AB12: 0.0825 | AC12: 0.0825 | AD12: 0.0825 | AE12: 0.0825 | AF12: 0.0825 | AG12: 0.0825 | AH12: 0.0825 | AI12: 0.0825 | AJ12: 0.0825 | AK12: 0.0825 | AL12: 0.0825 | AM12: 0.0825 | AN12: 0.0825 | AO12: 0.0825 | AP12: 0.0825 | AQ12: 0.0825 | AR12: 0.0825 | AS12: 0.0825 | AT12: 0.0825 | AU12: 0.0825
B13: Mortgage Payment Year | D13: 15 | E13: =+D13-1 -> 14 | F13: =+E13-1 -> 13 | G13: =+F13-1 -> 12 | H13: =+G13-1 -> 11 | I13: =+H13-1 -> 10 | J13: =+I13-1 -> 9 | K13: =+J13-1 -> 8 | L13: =+K13-1 -> 7 | ... S13: =+R13-1 -> 0
B14: Saving/CD Rate | D14: 0.048 | E14: 0.048 | F14: 0.048 | G14: 0.048 | H14: 0.048 | I14: 0.048 | J14: 0.048 | K14: 0.048 | L14: 0.048 | M14: 0.048 | N14: 0.048 | O14: 0.048 | P14: 0.048 | Q14: 0.048 | R14: 0.048 | S14: 0.048 | T14: 0.048 | U14: 0.048 | V14: 0.048 | W14: 0.048 | X14: 0.048 | Y14: 0.048 | Z14: 0.048 | AA14: 0.048 | AB14: 0.048 | AC14: 0.048 | AD14: 0.048 | AE14: 0.048 | AF14: 0.048 | AG14: 0.048 | AH14: 0.048 | AI14: 0.048 | AJ14: 0.048 | AK14: 0.048 | AL14: 0.048 | AM14: 0.048 | AN14: 0.048 | AO14: 0.048 | AP14: 0.048 | AQ14: 0.048 | AR14: 0.048 | AS14: 0.048 | AT14: 0.048 | AU14: 0.048
B15: Payroll Tax % (includes all) | D15: 0.26 | E15: 0.26 | F15: 0.26 | G15: 0.26 | H15: 0.26 | I15: 0.26 | J15: 0.26 | K15: 0.26 | L15: 0.26 | M15: 0.26 | N15: 0.26 | O15: 0.26 | P15: 0.26 | Q15: 0.26 | R15: 0.26 | S15: 0.26 | T15: 0.26 | U15: 0.26 | V15: 0.26 | W15: 0.26 | X15: 0.26 | Y15: 0.26 | Z15: 0.26 | AA15: 0.26 | AB15: 0.26 | AC15: 0.26 | AD15: 0.26 | AE15: 0.26 | AF15: 0.26 | AG15: 0.26 | AH15: 0.26 | AI15: 0.26 | AJ15: 0.26 | AK15: 0.26 | AL15: 0.26 | AM15: 0.26 | AN15: 0.26 | AO15: 0.26 | AP15: 0.26 | AQ15: 0.26 | AR15: 0.26 | AS15: 0.26 | AT15: 0.26 | AU15: 0.26
B17: #Years until Retirement for Husband | D17: 22.5 | E17: =+D17-1 -> 21.5 | F17: =+E17-1 -> 20.5 | G17: =+F17-1 -> 19.5 | H17: =+G17-1 -> 18.5 | I17: =+H17-1 -> 17.5 | J17: =+I17-1 -> 16.5 | K17: =+J17-1 -> 15.5 | L17: =+K17-1 -> 14.5 | ... AU17: =+AT17-1 -> -20.5
B18: #Years until Retirement for Wife | D18: 28 | E18: =+D18-1 -> 27 | F18: =+E18-1 -> 26 | G18: =+F18-1 -> 25 | H18: =+G18-1 -> 24 | I18: =+H18-1 -> 23 | J18: =+I18-1 -> 22 | K18: =+J18-1 -> 21 | L18: =+K18-1 -> 20 | ... AU18: =+AT18-1 -> -15
B20: Income | D20: 2025 | E20: =+D20+1 -> 2026 | F20: =+E20+1 -> 2027 | G20: =+F20+1 -> 2028 | H20: =+G20+1 -> 2029 | I20: =+H20+1 -> 2030 | J20: =+I20+1 -> 2031 | K20: =+J20+1 -> 2032 | L20: =+K20+1 -> 2033 | ... AU20: =+AT20+1 -> 2068
B21: Wife Annual Income | D21: 55000 | E21: =+D21*(1+E3) -> 57750 | F21: =+E21*(1+F3) -> 60060 | G21: =+F21*(1+G3) -> 62462.4 | H21: =+G21*(1+H3) -> 64960.896 | I21: =+H21*(1+I3) -> 67559.332 | J21: =+I21*(1+J3) -> 70261.705 | K21: =+J21*(1+K3) -> 73072.173 | L21: =+K21*(1+L3) -> 75995.06 | ... AG21: =+AF21*(1+AG3) -> 135277.15 | AH21: 20000 | AI21: 20000 | AJ21: =+AI21*(1+AJ3) -> 20000 | AK21: =+AJ21*(1+AK3) -> 20000 | AL21: =+AK21*(1+AL3) -> 20000 | AM21: =+AL21*(1+AM3) -> 20000 | AN21: 0 | AO21: 0 | AP21: =+AO21*(1+AP3) -> 0 | AQ21: =+AP21*(1+AQ3) -> 0 | AR21: =+AQ21*(1+AR3) -> 0 | AS21: =+AR21*(1+AS3) -> 0 | AT21: =+AS21*(1+AT3) -> 0 | AU21: =+AT21*(1+AU3) -> 0 | AV21: =SUM(D21:AU21) -> 2944060.9
B22: Wife Bonus | D22: 1000 | E22: 2000 | F22: 2000 | G22: 2000 | H22: 2000 | I22: 2000 | J22: 2000 | K22: 2000 | L22: 2000 | M22: 2000 | N22: 2000 | O22: 2000 | P22: 2000 | Q22: 2000 | R22: 2000 | S22: 2000 | T22: 2000 | U22: 2000 | V22: 2000 | W22: 2000 | X22: 2000 | Y22: 2000 | Z22: 2000 | AA22: 2000 | AB22: 2000 | AC22: 2000 | AD22: 2000 | AE22: 2000 | AF22: 2000 | AG22: 2000 | AV22: =SUM(D22:AU22) -> 59000
B23: Husband Annual Income | D23: 100000 | E23: =+D23*(1+E4) -> 102500 | F23: =+E23*(1+F4) -> 105062.5 | G23: =+F23*(1+G4) -> 107689.06 | H23: =+G23*(1+H4) -> 110381.29 | I23: =+H23*(1+I4) -> 113140.82 | J23: =+I23*(1+J4) -> 115969.34 | K23: =+J23*(1+K4) -> 118868.58 | L23: =+K23*(1+L4) -> 121840.29 | ... V23: =+U23*(1+V4) -> 155965.87 | W23: 75000 | X23: =+W23*(1+X4) -> 76875 | Y23: =+X23*(1+Y4) -> 78796.875 | Z23: =+Y23*(1+Z4) -> 80766.797 | AA23: =+Z23*(1+AA4) -> 82785.967 | AB23: 25000 | AC23: =+AB23*(1+AC4) -> 25000 | AD23: 25000 | AE23: 0 | AF23: 0 | AG23: 0 | AH23: 0 | AI23: 0 | AJ23: 0 | AK23: 0 | AL23: 0 | AM23: 0 | AN23: 0 | AO23: 0 | AP23: 0 | AQ23: 0 | AR23: 0 | AS23: 0 | AT23: 0 | AU23: 0 | AV23: =SUM(D23:AU23) -> 2863825.4
B24: Husband Bonus | D24: 14500 | E24: 11500 | F24: 12000 | G24: 12500 | H24: 12.5 | I24: 12.55 | J24: 14000 | K24: 14500 | L24: 15000 | M24: 15000 | N24: 15000 | O24: 16000 | P24: 16000 | Q24: 16000 | R24: 16000 | S24: 16500 | T24: 16500 | U24: 17000 | V24: 17000 | W24: 0 | X24: 0 | Y24: 0 | Z24: 0 | AA24: 0 | AB24: 0 | AC24: 0 | AV24: =SUM(D24:AU24) -> 255025.05
B25: Wife SS Payment | AJ25: 16140 | AK25: 16140 | AL25: 16140 | AM25: 16140 | AN25: 16140 | AO25: 16140 | AP25: 16140 | AQ25: 16140 | AR25: 16140 | AS25: 16140 | AT25: 16140 | AU25: 16140 | AV25: =SUM(D25:AU25) -> 193680
B26: Wife SS Payment | V26: 18620 | W26: 18620 | X26: 18620 | Y26: 18620 | Z26: 18620 | AA26: 18620 | AB26: 18620 | AC26: 18620 | AD26: 18620 | AE26: 18620 | AF26: 18620 | AG26: 18620 | AH26: 18620 | AI26: 18620 | AJ26: 18620 | AK26: 18620 | AV26: =SUM(D25:AU25) -> 193680
B27: 401K Withdrawal | AH27: 80000 | AI27: 80000 | AJ27: 80000 | AK27: 150000 | AL27: 150000 | AM27: 150000 | AN27: 150000 | AO27: 170000 | AP27: 250000 | AQ27: 2.525 | AR27: 2.55 | AS27: 2.575 | AT27: 400000 | AU27: 410000 | AV27: =SUM(D27:AU27) -> 2070007.6
B28: IRA Withdrawal Taxable | AH28: 15000 | AI28: 20000 | AJ28: 20000 | AK28: 5000 | AL28: 35000 | AM28: 40000 | AN28: 65000 | AO28: 48283
B29: IRA Withdrawal Non Taxable | AG29: 10000 | AH29: 50000 | AI29: 50000 | AJ29: 40665 | AK29: 50000 | AL29: 50000 | AM29: 50000 | AN29: 50000 | AO29: 50000 | AP29: 50000
B31: Total Income | D31: =SUM(D21:D30) -> 170500 | E31: =SUM(E21:E30) -> 173750 | F31: =SUM(F21:F30) -> 179122.5 | G31: =SUM(G21:G30) -> 184651.46 | H31: =SUM(H21:H30) -> 177354.69 | I31: =SUM(I21:I30) -> 182712.7 | J31: =SUM(J21:J30) -> 202231.05 | K31: =SUM(K21:K30) -> 208440.75 | ... AU31: =SUM(AU21:AU30) -> 426140 | AV31: =SUM(D31:AU31) -> 9382467
B33: Expenses
B34: Total Payroll Taxes | D34: =+(D31-D25-D25-D29)*D15 -> 44330 | E34: =+(E31-E25-E25-E29)*E15 -> 45175 | F34: =+(F31-F25-F25-F29)*F15 -> 46571.85 | G34: =+(G31-G25-G25-G29)*G15 -> 48009.38 | H34: =+(H31-H25-H25-H29)*H15 -> 46112.218 | I34: =+(I31-I25-I25-I29)*I15 -> 47505.303 | J34: =+(J31-J25-J25-J29)*J15 -> 52580.072 | K34: =+(K31-K25-K25-K29)*K15 -> 54194.595 | ... AU34: =+(AU31-AU25-AU25-AU29)*AU15 -> 102403.6 | AV34: =SUM(D34:AU34) -> 2221554.9
B35: Property Taxes | D35: 5500 | E35: =+D34*(1+E5) -> 45438.25 | F35: =+E34*(1+F5) -> 46304.375 | G35: =+F34*(1+G5) -> 47736.146 | H35: =+G34*(1+H5) -> 49209.615 | I35: =+H34*(1+I5) -> 47265.024 | J35: =+I34*(1+J5) -> 48692.935 | K35: =+J34*(1+K5) -> 53894.574 | L35: =+K34*(1+L5) -> 55549.46 | ... AU35: =+AT34*(1+AU5) -> 102298.69 | AV35: =SUM(D34:AU34) -> 2221554.9
B36: 401K Contribution-Wife | D36: =(+D21+D22)*D6 -> 8400 | E36: =(+E21+E22)*E6 -> 8962.5 | F36: =(+F21+F22)*F6 -> 9309 | G36: =(+G21+G22)*G6 -> 9669.36 | H36: =(+H21+H22)*H6 -> 10044.134 | I36: =(+I21+I22)*I6 -> 10433.9 | J36: =(+J21+J22)*J6 -> 10839.256 | K36: =(+K21+K22)*K6 -> 11260.826 | ... AU36: =(+AU21+AU22)*AU6 -> 0 | AV36: =SUM(D36:AU36) -> 432459.14
B37: 401K Contribution-Husband | D37: =(+D23+D24)*D6 -> 17175 | E37: =(+E23+E24)*E6 -> 17100 | F37: =(+F23+F24)*F6 -> 17559.375 | G37: =(+G23+G24)*G6 -> 18028.359 | H37: =(+H23+H24)*H6 -> 16559.068 | I37: =(+I23+I24)*I6 -> 16973.006 | J37: =(+J23+J24)*J6 -> 19495.401 | K37: =(+K23+K24)*K6 -> 20005.286 | ... AU37: =(+AU23+AU24)*AU6 -> 0 | AV37: =SUM(D37:AU37) -> 467827.56
B38: Roth IRA | D38: 3000 | E38: 4000 | F38: 4000 | G38: 4000 | H38: 4000 | I38: 0 | J38: 0 | K38: 0 | L38: 0 | M38: 0 | N38: 0 | O38: 0 | P38: 0 | Q38: 0 | R38: 0 | AB38: 2000 | AC38: 2000 | AD38: 2000 | AE38: 2000 | AF38: 2000 | AG38: 2000 | AV38: =SUM(D38:AU38) -> 31000
B39: Traditional IRA | J39: 4000 | K39: 4000 | L39: 4000 | M39: 4000 | N39: 4000 | O39: 4000 | P39: 4000 | Q39: 4000 | R39: 4000 | S39: 4000 | T39: 4000 | U39: 4000 | V39: 4000 | W39: 4000 | X39: 4000 | Y39: 4000 | Z39: 4000 | AA39: 2000 | AV39: =SUM(D39:AU39) -> 70000
B40: Husband-Child Support | D40: 10000 | E40: 5000 | F40: 0 | G40: 0 | H40: 0 | I40: 0 | J40: 0 | K40: 0 | L40: 0 | M40: 0 | N40: 0 | O40: 0 | P40: 0 | Q40: 0 | R40: 0 | S40: 0 | T40: 0 | U40: 0 | V40: 0 | W40: 0 | X40: 0 | Y40: 0 | Z40: 0 | AA40: 0 | AB40: 0 | AC40: 0 | AD40: 0 | AE40: 0 | AF40: 0 | AG40: 0 | AH40: 0 | AI40: 0 | AJ40: 0 | AK40: 0 | AL40: 0 | AM40: 0 | AN40: 0 | AO40: 0 | AP40: 0 | AQ40: 0 | AR40: 0 | AS40: 0 | AT40: 0 | AU40: 0 | AV40: =SUM(D40:AU40) -> 15000
B41: Mortgage (See Mortgage Sch Tab) | D41: =-Mortgage!$F$1 -> 10953.002 | E41: =-Mortgage!$F$1 -> 10953.002 | F41: =-Mortgage!$F$1 -> 10953.002 | G41: =-Mortgage!$F$1 -> 10953.002 | H41: =-Mortgage!$F$1 -> 10953.002 | I41: =-Mortgage!$F$1 -> 10953.002 | J41: =-Mortgage!$F$1 -> 10953.002 | K41: =-Mortgage!$F$1 -> 10953.002 | ... R41: =-Mortgage!$F$1 -> 10953.002 | AV41: =SUM(D41:AU41) -> 164295.03
B42: Phone/Internet/Electrical | D42: 1000 | E42: =+D42*(1+E$5) -> 1025 | F42: =+E42*(1+F$5) -> 1050.625 | G42: =+F42*(1+G$5) -> 1076.8906 | H42: =+G42*(1+H$5) -> 1103.8129 | I42: =+H42*(1+I$5) -> 1131.4082 | J42: =+I42*(1+J$5) -> 1159.6934 | K42: =+J42*(1+K$5) -> 1188.6858 | L42: =+K42*(1+L$5) -> 1218.4029 | ... AU42: =+AT42*(1+AU$5) -> 2891.5201 | AV42: =SUM(D42:AU42) -> 78552.323
B43: Heating | D43: 1200 | E43: =+D43*(1+E$5) -> 1230 | F43: =+E43*(1+F$5) -> 1260.75 | G43: =+F43*(1+G$5) -> 1292.2687 | H43: =+G43*(1+H$5) -> 1324.5755 | I43: =+H43*(1+I$5) -> 1357.6899 | J43: =+I43*(1+J$5) -> 1391.6321 | K43: =+J43*(1+K$5) -> 1426.4229 | L43: =+K43*(1+L$5) -> 1462.0835 | ... AU43: =+AT43*(1+AU$5) -> 3469.8241 | AV43: =SUM(D43:AU43) -> 94262.788
B44: Car - Gas/Maintenance | D44: 2000 | E44: =+D44*(1+E$5) -> 2050 | F44: =+E44*(1+F$5) -> 2101.25 | G44: =+F44*(1+G$5) -> 2153.7812 | H44: =+G44*(1+H$5) -> 2207.6258 | I44: =+H44*(1+I$5) -> 2262.8164 | J44: =+I44*(1+J$5) -> 2319.3868 | K44: =+J44*(1+K$5) -> 2377.3715 | L44: =+K44*(1+L$5) -> 2436.8058 | ... AU44: =+AT44*(1+AU$5) -> 5783.0402 | AV44: =SUM(D44:AU44) -> 157104.65
...

Sheet Mortgage
A1: Mortgage Payment Schedule | D1: Mth/Pay | E1: =PMT(0.00604,180,100000,0,0) -> -912.75015 | F1: =+E1*12 -> -10953.002 | G1: Annual/Pay
E2: =+E1*180 -> -164295.03 | F2: Cost of loan
E3: =+E2+C6 -> -64295.026 | F3: Interest on loan
C4: Mortgage | E4: Principal
A5: Payment | B5: PPMT | C5: Balance | D5: End of Yr | E5: Paid
C6: 100000
A7: 1 | B7: =PPMT(0.00604,A7,180,100000,0) -> -308.75015 | C7: =+C6+B7 -> 99691.25
A8: =+A7+1 -> 2 | B8: =PPMT(0.00604,A8,180,100000,0) -> -310.615 | C8: =+C7+B8 -> 99380.635
A9: =+A8+1 -> 3 | B9: =PPMT(0.00604,A9,180,100000,0) -> -312.49111 | C9: =+C8+B9 -> 99068.144
A10: =+A9+1 -> 4 | B10: =PPMT(0.00604,A10,180,100000,0) -> -314.37856 | C10: =+C9+B10 -> 98753.765
A11: =+A10+1 -> 5 | B11: =PPMT(0.00604,A11,180,100000,0) -> -316.27741 | C11: =+C10+B11 -> 98437.488
A12: =+A11+1 -> 6 | B12: =PPMT(0.00604,A12,180,100000,0) -> -318.18772 | C12: =+C11+B12 -> 98119.3
A13: =+A12+1 -> 7 | B13: =PPMT(0.00604,A13,180,100000,0) -> -320.10957 | C13: =+C12+B13 -> 97799.19
A14: =+A13+1 -> 8 | B14: =PPMT(0.00604,A14,180,100000,0) -> -322.04304 | C14: =+C13+B14 -> 97477.147
A15: =+A14+1 -> 9 | B15: =PPMT(0.00604,A15,180,100000,0) -> -323.98818 | C15: =+C14+B15 -> 97153.159
A16: =+A15+1 -> 10 | B16: =PPMT(0.00604,A16,180,100000,0) -> -325.94507 | C16: =+C15+B16 -> 96827.214
A17: =+A16+1 -> 11 | B17: =PPMT(0.00604,A17,180,100000,0) -> -327.91377 | C17: =+C16+B17 -> 96499.3
A18: =+A17+1 -> 12 | B18: =PPMT(0.00604,A18,180,100000,0) -> -329.89437 | C18: =+C17+B18 -> 96169.406 | D18: 2025 | E18: =+C6-C18 -> 3830.5939 | F18: =SUM(B7:B18) -> -3830.5939 | G18: =+E18+F18 -> -7.2759576e-12
A19: =+A18+1 -> 13 | B19: =PPMT(0.00604,A19,180,100000,0) -> -331.88693 | C19: =+C18+B19 -> 95837.519
A20: =+A19+1 -> 14 | B20: =PPMT(0.00604,A20,180,100000,0) -> -333.89153 | C20: =+C19+B20 -> 95503.628
A21: =+A20+1 -> 15 | B21: =PPMT(0.00604,A21,180,100000,0) -> -335.90824 | C21: =+C20+B21 -> 95167.719
A22: =+A21+1 -> 16 | B22: =PPMT(0.00604,A22,180,100000,0) -> -337.93712 | C22: =+C21+B22 -> 94829.782
A23: =+A22+1 -> 17 | B23: =PPMT(0.00604,A23,180,100000,0) -> -339.97826 | C23: =+C22+B23 -> 94489.804
A24: =+A23+1 -> 18 | B24: =PPMT(0.00604,A24,180,100000,0) -> -342.03173 | C24: =+C23+B24 -> 94147.772
A25: =+A24+1 -> 19 | B25: =PPMT(0.00604,A25,180,100000,0) -> -344.0976 | C25: =+C24+B25 -> 93803.675
A26: =+A25+1 -> 20 | B26: =PPMT(0.00604,A26,180,100000,0) -> -346.17595 | C26: =+C25+B26 -> 93457.499
A27: =+A26+1 -> 21 | B27: =PPMT(0.00604,A27,180,100000,0) -> -348.26686 | C27: =+C26+B27 -> 93109.232
A28: =+A27+1 -> 22 | B28: =PPMT(0.00604,A28,180,100000,0) -> -350.37039 | C28: =+C27+B28 -> 92758.861
A29: =+A28+1 -> 23 | B29: =PPMT(0.00604,A29,180,100000,0) -> -352.48662 | C29: =+C28+B29 -> 92406.375
A30: =+A29+1 -> 24 | B30: =PPMT(0.00604,A30,180,100000,0) -> -354.61564 | C30: =+C29+B30 -> 92051.759 | D30: =+D18+1 -> 2026 | E30: =+C18-C30 -> 4117.6469 | F30: =SUM(B19:B30) -> -4117.6469 | G30: =+E30+F30 -> 0
A31: =+A30+1 -> 25 | B31: =PPMT(0.00604,A31,180,100000,0) -> -356.75752 | C31: =+C30+B31 -> 91695.002
A32: =+A31+1 -> 26 | B32: =PPMT(0.00604,A32,180,100000,0) -> -358.91234 | C32: =+C31+B32 -> 91336.089
A33: =+A32+1 -> 27 | B33: =PPMT(0.00604,A33,180,100000,0) -> -361.08017 | C33: =+C32+B33 -> 90975.009
A34: =+A33+1 -> 28 | B34: =PPMT(0.00604,A34,180,100000,0) -> -363.26109 | C34: =+C33+B34 -> 90611.748
A35: =+A34+1 -> 29 | B35: =PPMT(0.00604,A35,180,100000,0) -> -365.45519 | C35: =+C34+B35 -> 90246.293
A36: =+A35+1 -> 30 | B36: =PPMT(0.00604,A36,180,100000,0) -> -367.66254 | C36: =+C35+B36 -> 89878.63
A37: =+A36+1 -> 31 | B37: =PPMT(0.00604,A37,180,100000,0) -> -369.88322 | C37: =+C36+B37 -> 89508.747
A38: =+A37+1 -> 32 | B38: =PPMT(0.00604,A38,180,100000,0) -> -372.11731 | C38: =+C37+B38 -> 89136.63
A39: =+A38+1 -> 33 | B39: =PPMT(0.00604,A39,180,100000,0) -> -374.3649 | C39: =+C38+B39 -> 88762.265
A40: =+A39+1 -> 34 | B40: =PPMT(0.00604,A40,180,100000,0) -> -376.62607 | C40: =+C39+B40 -> 88385.639
...
